<?xml version='1.0' encoding='UTF-8'?>
<mujoco>
  <option gravity="0 0 -9.81" timestep="0.002">
    <flag warmstart="enable"/>
  </option>
  <visual>
    <global offwidth="800" offheight="800"/>
    <quality shadowsize="4096"/>
    <map force="0.1" fogstart="3" fogend="5" znear="0.1" zfar="50"/>
  </visual>
  <asset>
    <texture type="skybox" builtin="gradient" rgb1="0.3 0.5 0.7" rgb2="0 0 0" width="512" height="512"/>
    <material name="arm1" rgba="0.8 0.3 0.3 1"/>
    <material name="arm2" rgba="0.3 0.8 0.3 1"/>
    <material name="arm3" rgba="0.3 0.3 0.8 1"/>
  </asset>
  <option gravity="0 0 -9.81" timestep="0.001">
    <flag warmstart="enable"/>
  </option>
  <default>
    <joint damping="1.0" armature="0.1" frictionloss="0.1"/>
  </default>
  <worldbody>
    <body name="base" pos="-0.3950124685830086 -0.3092843358865642 0.1">
      <geom name="base_geom" type="cylinder" size="0.05 0.01" material="arm1"/>
      <joint name="joint1" type="hinge" axis="0 0 1" pos="0 0 -0.05"/>
      <site name="site_1" pos="0 0 0"/>
      <geom name="capsule_1_2" type="capsule" fromto="0 0 0 -0.6153042500230126 0.6754187359417383 0.0" size="0.01" material="arm2"/>
      <site name="conn_site_1_2" pos="-0.6153042500230126 0.6754187359417383 0.0"/>
      <body name="link3" pos="0.6083105595032163 0.681724322695326 0">
        <geom name="link3_geom" type="cylinder" size="0.05 0.01" material="arm1"/>
        <joint name="joint3" type="hinge" axis="0 0 1" pos="0 0 -0.05"/>
        <site name="site_3" pos="0 0 0"/>
        <body name="link4" pos="1.7867019090797922 -2.078654465924599 0">
          <geom name="link4_geom" type="cylinder" size="0.05 0.01" material="arm1"/>
          <joint name="joint4" type="hinge" axis="0 0 1" pos="0 0 -0.05"/>
          <site name="site_4" pos="0 0 0"/>
          <geom name="capsule_4_2" type="capsule" fromto="0 0 0 -3.0103167186060213 2.0723488791710114 0.0" size="0.01" material="arm2"/>
          <site name="conn_site_4_2" pos="-3.0103167186060213 2.0723488791710114 0.0"/>
        </body>
        <geom name="capsule_3_4" type="capsule" fromto="0 0 0 1.7867019090797922 -2.078654465924599 0" size="0.01" material="arm2"/>
      </body>
      <geom name="capsule_1_3" type="capsule" fromto="0 0 0 0.6083105595032163 0.681724322695326 0" size="0.01" material="arm2"/>
    </body>
    <body name="end2" pos="-1.0103167186060211 0.36613440005517417 0.1">
      <geom name="end2_geom" type="cylinder" size="0.05 0.01" material="arm1"/>
      <site name="site_2" pos="0 0 0"/>
    </body>
  </worldbody>
  <tendon>
    <spatial name="tendon_1_2" limited="true" range="0 0.0001" width="0.003" rgba="0.8 0.8 0.8 1">
      <site site="conn_site_1_2"/>
      <site site="site_2"/>
    </spatial>
    <spatial name="tendon_4_2" limited="true" range="0 0.0001" width="0.003" rgba="0.8 0.8 0.8 1">
      <site site="conn_site_4_2"/>
      <site site="site_2"/>
    </spatial>
  </tendon>
  <actuator>
    <position name="vel_joint1" joint="joint1" kv="10.0" ctrlrange="-3.14 3.14"/>
    <position name="vel_joint3" joint="joint3" kv="10.0" ctrlrange="-3.14 3.14"/>
  </actuator>
</mujoco>
