<?xml version='1.0' encoding='UTF-8'?>
<mujoco>
  <option gravity="0 0 -9.81" timestep="0.002">
    <flag warmstart="enable"/>
  </option>
  <visual>
    <global offwidth="800" offheight="800"/>
    <quality shadowsize="4096"/>
    <map force="0.1" fogstart="3" fogend="5" znear="0.1" zfar="50"/>
  </visual>
  <asset>
    <texture type="skybox" builtin="gradient" rgb1="0.3 0.5 0.7" rgb2="0 0 0" width="512" height="512"/>
    <material name="arm1" rgba="0.8 0.3 0.3 1"/>
    <material name="arm2" rgba="0.3 0.8 0.3 1"/>
    <material name="arm3" rgba="0.3 0.3 0.8 1"/>
  </asset>
  <option gravity="0 0 -9.81" timestep="0.001">
    <flag warmstart="enable"/>
  </option>
  <default>
    <joint damping="1.0" armature="0.1" frictionloss="0.1"/>
  </default>
  <worldbody>
    <body name="base" pos="0.0 0.0 0.1">
      <geom name="base_geom" type="cylinder" size="0.05 0.01" material="arm1"/>
      <joint name="joint1" type="hinge" axis="0 0 1" pos="0 0 -0.05"/>
      <site name="site_1" pos="0 0 0"/>
      <body name="link2" pos="0.5 0.0 0">
        <geom name="link2_geom" type="cylinder" size="0.05 0.01" material="arm1"/>
        <joint name="joint2" type="hinge" axis="0 0 1" pos="0 0 -0.05"/>
        <site name="site_2" pos="0 0 0"/>
        <body name="link3" pos="0.5 0.5 0">
          <geom name="link3_geom" type="cylinder" size="0.05 0.01" material="arm1"/>
          <joint name="joint3" type="hinge" axis="0 0 1" pos="0 0 -0.05"/>
          <site name="site_3" pos="0 0 0"/>
          <body name="link4" pos="-1.0 0.0 0">
            <geom name="link4_geom" type="cylinder" size="0.05 0.01" material="arm1"/>
            <joint name="joint4" type="hinge" axis="0 0 1" pos="0 0 -0.05"/>
            <site name="site_4" pos="0 0 0"/>
          </body>
          <geom name="capsule_3_4" type="capsule" fromto="0 0 0 -1.0 0.0 0" size="0.01" material="arm2"/>
          <geom name="capsule_3_6" type="capsule" fromto="0 0 0 0.5 0.0 0.0" size="0.01" material="arm2"/>
          <site name="conn_site_3_6" pos="0.5 0.0 0.0"/>
        </body>
        <geom name="capsule_2_3" type="capsule" fromto="0 0 0 0.5 0.5 0" size="0.01" material="arm2"/>
        <geom name="capsule_2_5" type="capsule" fromto="0 0 0 0.19999999999999996 -0.3 0.0" size="0.01" material="arm2"/>
        <site name="conn_site_2_5" pos="0.19999999999999996 -0.3 0.0"/>
      </body>
      <geom name="capsule_1_2" type="capsule" fromto="0 0 0 0.5 0.0 0" size="0.01" material="arm2"/>
    </body>
    <body name="end5" pos="0.7 -0.3 0.1">
      <geom name="end5_geom" type="cylinder" size="0.05 0.01" material="arm1"/>
      <site name="site_5" pos="0 0 0"/>
    </body>
    <body name="end6" pos="1.5 0.5 0.1">
      <geom name="end6_geom" type="cylinder" size="0.05 0.01" material="arm1"/>
      <site name="site_6" pos="0 0 0"/>
    </body>
  </worldbody>
  <tendon>
    <spatial name="tendon_3_6" limited="true" range="0 0.0001" width="0.003" rgba="0.8 0.8 0.8 1">
      <site site="conn_site_3_6"/>
      <site site="site_6"/>
    </spatial>
    <spatial name="tendon_2_5" limited="true" range="0 0.0001" width="0.003" rgba="0.8 0.8 0.8 1">
      <site site="conn_site_2_5"/>
      <site site="site_5"/>
    </spatial>
  </tendon>
  <actuator>
    <position name="pos_joint1" joint="joint1" kp="10.0" ctrlrange="-3.14159 3.14159"/>
    <velocity name="vel_joint1" joint="joint1" kv="1.0"/>
  </actuator>
</mujoco>
